from pycloudia.cloud.exceptions import PackageError


class AuthError(PackageError):
    pass
