from pycloudia.activities.exceptions import PackageError


class AuthError(PackageError):
    pass
